[2018-05-04 10:54:17,059] {models.py:167} INFO - Filling up the DagBag from /Users/sam/All-Program/App/PropertyClassification/dags/test_pipeline.py
[2018-05-04 10:54:20,381] {base_task_runner.py:112} INFO - Running: ['bash', '-c', 'airflow run PropertyClassification_test_pipeline test_on_new_images 2018-05-04T10:48:02.829442 --job_id 17 --raw -sd /Users/sam/All-Program/App/PropertyClassification/dags/test_pipeline.py']
[2018-05-04 10:54:20,713] {base_task_runner.py:95} INFO - Subtask: [2018-05-04 10:54:20,712] {__init__.py:57} INFO - Using executor SequentialExecutor
[2018-05-04 10:54:21,119] {base_task_runner.py:95} INFO - Subtask: [2018-05-04 10:54:21,119] {models.py:167} INFO - Filling up the DagBag from /Users/sam/All-Program/App/PropertyClassification/dags/test_pipeline.py
[2018-05-04 10:54:24,385] {base_task_runner.py:95} INFO - Subtask: [2018-05-04 10:54:24,385] {models.py:1126} INFO - Dependencies all met for <TaskInstance: PropertyClassification_test_pipeline.test_on_new_images 2018-05-04 10:48:02.829442 [queued]>
[2018-05-04 10:54:24,391] {base_task_runner.py:95} INFO - Subtask: [2018-05-04 10:54:24,391] {models.py:1126} INFO - Dependencies all met for <TaskInstance: PropertyClassification_test_pipeline.test_on_new_images 2018-05-04 10:48:02.829442 [queued]>
[2018-05-04 10:54:24,391] {base_task_runner.py:95} INFO - Subtask: [2018-05-04 10:54:24,391] {models.py:1318} INFO - 
[2018-05-04 10:54:24,391] {base_task_runner.py:95} INFO - Subtask: --------------------------------------------------------------------------------
[2018-05-04 10:54:24,391] {base_task_runner.py:95} INFO - Subtask: Starting attempt 1 of 2
[2018-05-04 10:54:24,392] {base_task_runner.py:95} INFO - Subtask: --------------------------------------------------------------------------------
[2018-05-04 10:54:24,392] {base_task_runner.py:95} INFO - Subtask: 
[2018-05-04 10:54:24,400] {base_task_runner.py:95} INFO - Subtask: [2018-05-04 10:54:24,400] {models.py:1342} INFO - Executing <Task(PythonOperator): test_on_new_images> on 2018-05-04 10:48:02.829442
[2018-05-04 10:54:24,418] {base_task_runner.py:95} INFO - Subtask: [2018-05-04 10:54:24,418] {test.py:103} INFO - INITIATING TEST ........
[2018-05-04 10:54:24,419] {base_task_runner.py:95} INFO - Subtask: [2018-05-04 10:54:24,418] {models.py:1417} ERROR - [Errno 2] No such file or directory: '/Users/sam/All-Program/App-DataSet/HouseClassification/checkpoints/sam_new/aerial_cropped/resent'
[2018-05-04 10:54:24,420] {base_task_runner.py:95} INFO - Subtask: Traceback (most recent call last):
[2018-05-04 10:54:24,420] {base_task_runner.py:95} INFO - Subtask:   File "/Users/sam/App-Setup/anaconda/envs/anaconda35/lib/python3.5/site-packages/airflow/models.py", line 1374, in run
[2018-05-04 10:54:24,420] {base_task_runner.py:95} INFO - Subtask:     result = task_copy.execute(context=context)
[2018-05-04 10:54:24,420] {base_task_runner.py:95} INFO - Subtask:   File "/Users/sam/App-Setup/anaconda/envs/anaconda35/lib/python3.5/site-packages/airflow/operators/python_operator.py", line 80, in execute
[2018-05-04 10:54:24,420] {base_task_runner.py:95} INFO - Subtask:     return_value = self.python_callable(*self.op_args, **self.op_kwargs)
[2018-05-04 10:54:24,420] {base_task_runner.py:95} INFO - Subtask:   File "/Users/sam/All-Program/App/PropertyClassification/jobs/train_cv_test.py", line 193, in test_new
[2018-05-04 10:54:24,420] {base_task_runner.py:95} INFO - Subtask:     dump_stats=True)
[2018-05-04 10:54:24,420] {base_task_runner.py:95} INFO - Subtask:   File "/Users/sam/All-Program/App/PropertyClassification/src/conv_net/test.py", line 113, in run
[2018-05-04 10:54:24,420] {base_task_runner.py:95} INFO - Subtask:     checkpoint_paths = self.get_checkpoint_path(which_checkpoint)
[2018-05-04 10:54:24,420] {base_task_runner.py:95} INFO - Subtask:   File "/Users/sam/All-Program/App/PropertyClassification/src/conv_net/train.py", line 106, in get_checkpoint_path
[2018-05-04 10:54:24,420] {base_task_runner.py:95} INFO - Subtask:     checkpoints = [str(filename.split('.')[0]) for filename in os.listdir(self.ckpt_path)
[2018-05-04 10:54:24,420] {base_task_runner.py:95} INFO - Subtask: FileNotFoundError: [Errno 2] No such file or directory: '/Users/sam/All-Program/App-DataSet/HouseClassification/checkpoints/sam_new/aerial_cropped/resent'
[2018-05-04 10:54:24,420] {base_task_runner.py:95} INFO - Subtask: [2018-05-04 10:54:24,420] {models.py:1433} INFO - Marking task as UP_FOR_RETRY
[2018-05-04 10:54:24,429] {base_task_runner.py:95} INFO - Subtask: [2018-05-04 10:54:24,429] {models.py:1462} ERROR - [Errno 2] No such file or directory: '/Users/sam/All-Program/App-DataSet/HouseClassification/checkpoints/sam_new/aerial_cropped/resent'
[2018-05-04 10:54:24,429] {base_task_runner.py:95} INFO - Subtask: /Users/sam/App-Setup/anaconda/envs/anaconda35/lib/python3.5/site-packages/airflow/ti_deps/deps/base_ti_dep.py:94: PendingDeprecationWarning: generator '_get_dep_statuses' raised StopIteration
[2018-05-04 10:54:24,429] {base_task_runner.py:95} INFO - Subtask:   for dep_status in self._get_dep_statuses(ti, session, dep_context):
[2018-05-04 10:54:24,430] {base_task_runner.py:95} INFO - Subtask: Traceback (most recent call last):
[2018-05-04 10:54:24,430] {base_task_runner.py:95} INFO - Subtask:   File "/Users/sam/App-Setup/anaconda/envs/anaconda35/bin/airflow", line 28, in <module>
[2018-05-04 10:54:24,431] {base_task_runner.py:95} INFO - Subtask:     args.func(args)
[2018-05-04 10:54:24,431] {base_task_runner.py:95} INFO - Subtask:   File "/Users/sam/App-Setup/anaconda/envs/anaconda35/lib/python3.5/site-packages/airflow/bin/cli.py", line 422, in run
[2018-05-04 10:54:24,431] {base_task_runner.py:95} INFO - Subtask:     pool=args.pool,
[2018-05-04 10:54:24,431] {base_task_runner.py:95} INFO - Subtask:   File "/Users/sam/App-Setup/anaconda/envs/anaconda35/lib/python3.5/site-packages/airflow/utils/db.py", line 53, in wrapper
[2018-05-04 10:54:24,431] {base_task_runner.py:95} INFO - Subtask:     result = func(*args, **kwargs)
[2018-05-04 10:54:24,431] {base_task_runner.py:95} INFO - Subtask:   File "/Users/sam/App-Setup/anaconda/envs/anaconda35/lib/python3.5/site-packages/airflow/models.py", line 1374, in run
[2018-05-04 10:54:24,431] {base_task_runner.py:95} INFO - Subtask:     result = task_copy.execute(context=context)
[2018-05-04 10:54:24,431] {base_task_runner.py:95} INFO - Subtask:   File "/Users/sam/App-Setup/anaconda/envs/anaconda35/lib/python3.5/site-packages/airflow/operators/python_operator.py", line 80, in execute
[2018-05-04 10:54:24,431] {base_task_runner.py:95} INFO - Subtask:     return_value = self.python_callable(*self.op_args, **self.op_kwargs)
[2018-05-04 10:54:24,431] {base_task_runner.py:95} INFO - Subtask:   File "/Users/sam/All-Program/App/PropertyClassification/jobs/train_cv_test.py", line 193, in test_new
[2018-05-04 10:54:24,431] {base_task_runner.py:95} INFO - Subtask:     dump_stats=True)
[2018-05-04 10:54:24,431] {base_task_runner.py:95} INFO - Subtask:   File "/Users/sam/All-Program/App/PropertyClassification/src/conv_net/test.py", line 113, in run
[2018-05-04 10:54:24,431] {base_task_runner.py:95} INFO - Subtask:     checkpoint_paths = self.get_checkpoint_path(which_checkpoint)
[2018-05-04 10:54:24,431] {base_task_runner.py:95} INFO - Subtask:   File "/Users/sam/All-Program/App/PropertyClassification/src/conv_net/train.py", line 106, in get_checkpoint_path
[2018-05-04 10:54:24,432] {base_task_runner.py:95} INFO - Subtask:     checkpoints = [str(filename.split('.')[0]) for filename in os.listdir(self.ckpt_path)
[2018-05-04 10:54:24,432] {base_task_runner.py:95} INFO - Subtask: FileNotFoundError: [Errno 2] No such file or directory: '/Users/sam/All-Program/App-DataSet/HouseClassification/checkpoints/sam_new/aerial_cropped/resent'
[2018-05-04 10:54:25,388] {jobs.py:2083} INFO - Task exited with return code 1
[2018-05-04 10:56:37,972] {models.py:167} INFO - Filling up the DagBag from /Users/sam/All-Program/App/PropertyClassification/dags/test_pipeline.py
[2018-05-04 10:56:41,143] {base_task_runner.py:112} INFO - Running: ['bash', '-c', 'airflow run PropertyClassification_test_pipeline test_on_new_images 2018-05-04T10:48:02.829442 --job_id 21 --raw -sd /Users/sam/All-Program/App/PropertyClassification/dags/test_pipeline.py']
[2018-05-04 10:56:41,510] {base_task_runner.py:95} INFO - Subtask: [2018-05-04 10:56:41,509] {__init__.py:57} INFO - Using executor SequentialExecutor
[2018-05-04 10:56:41,957] {base_task_runner.py:95} INFO - Subtask: [2018-05-04 10:56:41,956] {models.py:167} INFO - Filling up the DagBag from /Users/sam/All-Program/App/PropertyClassification/dags/test_pipeline.py
[2018-05-04 10:56:45,073] {base_task_runner.py:95} INFO - Subtask: [2018-05-04 10:56:45,072] {models.py:1126} INFO - Dependencies all met for <TaskInstance: PropertyClassification_test_pipeline.test_on_new_images 2018-05-04 10:48:02.829442 [queued]>
[2018-05-04 10:56:45,077] {base_task_runner.py:95} INFO - Subtask: [2018-05-04 10:56:45,077] {models.py:1126} INFO - Dependencies all met for <TaskInstance: PropertyClassification_test_pipeline.test_on_new_images 2018-05-04 10:48:02.829442 [queued]>
[2018-05-04 10:56:45,077] {base_task_runner.py:95} INFO - Subtask: [2018-05-04 10:56:45,077] {models.py:1318} INFO - 
[2018-05-04 10:56:45,078] {base_task_runner.py:95} INFO - Subtask: --------------------------------------------------------------------------------
[2018-05-04 10:56:45,078] {base_task_runner.py:95} INFO - Subtask: Starting attempt 2 of 2
[2018-05-04 10:56:45,078] {base_task_runner.py:95} INFO - Subtask: --------------------------------------------------------------------------------
[2018-05-04 10:56:45,078] {base_task_runner.py:95} INFO - Subtask: 
[2018-05-04 10:56:45,087] {base_task_runner.py:95} INFO - Subtask: [2018-05-04 10:56:45,087] {models.py:1342} INFO - Executing <Task(PythonOperator): test_on_new_images> on 2018-05-04 10:48:02.829442
[2018-05-04 10:56:45,107] {base_task_runner.py:95} INFO - Subtask: [2018-05-04 10:56:45,106] {test.py:103} INFO - INITIATING TEST ........
[2018-05-04 10:56:45,108] {base_task_runner.py:95} INFO - Subtask: [2018-05-04 10:56:45,107] {models.py:1417} ERROR - [Errno 2] No such file or directory: '/Users/sam/All-Program/App-DataSet/HouseClassification/checkpoints/sam_new/aerial_cropped/resent'
[2018-05-04 10:56:45,108] {base_task_runner.py:95} INFO - Subtask: Traceback (most recent call last):
[2018-05-04 10:56:45,108] {base_task_runner.py:95} INFO - Subtask:   File "/Users/sam/App-Setup/anaconda/envs/anaconda35/lib/python3.5/site-packages/airflow/models.py", line 1374, in run
[2018-05-04 10:56:45,108] {base_task_runner.py:95} INFO - Subtask:     result = task_copy.execute(context=context)
[2018-05-04 10:56:45,108] {base_task_runner.py:95} INFO - Subtask:   File "/Users/sam/App-Setup/anaconda/envs/anaconda35/lib/python3.5/site-packages/airflow/operators/python_operator.py", line 80, in execute
[2018-05-04 10:56:45,108] {base_task_runner.py:95} INFO - Subtask:     return_value = self.python_callable(*self.op_args, **self.op_kwargs)
[2018-05-04 10:56:45,108] {base_task_runner.py:95} INFO - Subtask:   File "/Users/sam/All-Program/App/PropertyClassification/jobs/train_cv_test.py", line 193, in test_new
[2018-05-04 10:56:45,108] {base_task_runner.py:95} INFO - Subtask:     dump_stats=True)
[2018-05-04 10:56:45,108] {base_task_runner.py:95} INFO - Subtask:   File "/Users/sam/All-Program/App/PropertyClassification/src/conv_net/test.py", line 113, in run
[2018-05-04 10:56:45,109] {base_task_runner.py:95} INFO - Subtask:     checkpoint_paths = self.get_checkpoint_path(which_checkpoint)
[2018-05-04 10:56:45,109] {base_task_runner.py:95} INFO - Subtask:   File "/Users/sam/All-Program/App/PropertyClassification/src/conv_net/train.py", line 106, in get_checkpoint_path
[2018-05-04 10:56:45,109] {base_task_runner.py:95} INFO - Subtask:     checkpoints = [str(filename.split('.')[0]) for filename in os.listdir(self.ckpt_path)
[2018-05-04 10:56:45,109] {base_task_runner.py:95} INFO - Subtask: FileNotFoundError: [Errno 2] No such file or directory: '/Users/sam/All-Program/App-DataSet/HouseClassification/checkpoints/sam_new/aerial_cropped/resent'
[2018-05-04 10:56:45,109] {base_task_runner.py:95} INFO - Subtask: [2018-05-04 10:56:45,109] {models.py:1439} INFO - All retries failed; marking task as FAILED
[2018-05-04 10:56:45,117] {base_task_runner.py:95} INFO - Subtask: [2018-05-04 10:56:45,117] {models.py:1462} ERROR - [Errno 2] No such file or directory: '/Users/sam/All-Program/App-DataSet/HouseClassification/checkpoints/sam_new/aerial_cropped/resent'
[2018-05-04 10:56:45,118] {base_task_runner.py:95} INFO - Subtask: /Users/sam/App-Setup/anaconda/envs/anaconda35/lib/python3.5/site-packages/airflow/ti_deps/deps/base_ti_dep.py:94: PendingDeprecationWarning: generator '_get_dep_statuses' raised StopIteration
[2018-05-04 10:56:45,118] {base_task_runner.py:95} INFO - Subtask:   for dep_status in self._get_dep_statuses(ti, session, dep_context):
[2018-05-04 10:56:45,119] {base_task_runner.py:95} INFO - Subtask: Traceback (most recent call last):
[2018-05-04 10:56:45,119] {base_task_runner.py:95} INFO - Subtask:   File "/Users/sam/App-Setup/anaconda/envs/anaconda35/bin/airflow", line 28, in <module>
[2018-05-04 10:56:45,119] {base_task_runner.py:95} INFO - Subtask:     args.func(args)
[2018-05-04 10:56:45,119] {base_task_runner.py:95} INFO - Subtask:   File "/Users/sam/App-Setup/anaconda/envs/anaconda35/lib/python3.5/site-packages/airflow/bin/cli.py", line 422, in run
[2018-05-04 10:56:45,119] {base_task_runner.py:95} INFO - Subtask:     pool=args.pool,
[2018-05-04 10:56:45,119] {base_task_runner.py:95} INFO - Subtask:   File "/Users/sam/App-Setup/anaconda/envs/anaconda35/lib/python3.5/site-packages/airflow/utils/db.py", line 53, in wrapper
[2018-05-04 10:56:45,119] {base_task_runner.py:95} INFO - Subtask:     result = func(*args, **kwargs)
[2018-05-04 10:56:45,119] {base_task_runner.py:95} INFO - Subtask:   File "/Users/sam/App-Setup/anaconda/envs/anaconda35/lib/python3.5/site-packages/airflow/models.py", line 1374, in run
[2018-05-04 10:56:45,119] {base_task_runner.py:95} INFO - Subtask:     result = task_copy.execute(context=context)
[2018-05-04 10:56:45,119] {base_task_runner.py:95} INFO - Subtask:   File "/Users/sam/App-Setup/anaconda/envs/anaconda35/lib/python3.5/site-packages/airflow/operators/python_operator.py", line 80, in execute
[2018-05-04 10:56:45,120] {base_task_runner.py:95} INFO - Subtask:     return_value = self.python_callable(*self.op_args, **self.op_kwargs)
[2018-05-04 10:56:45,120] {base_task_runner.py:95} INFO - Subtask:   File "/Users/sam/All-Program/App/PropertyClassification/jobs/train_cv_test.py", line 193, in test_new
[2018-05-04 10:56:45,120] {base_task_runner.py:95} INFO - Subtask:     dump_stats=True)
[2018-05-04 10:56:45,120] {base_task_runner.py:95} INFO - Subtask:   File "/Users/sam/All-Program/App/PropertyClassification/src/conv_net/test.py", line 113, in run
[2018-05-04 10:56:45,120] {base_task_runner.py:95} INFO - Subtask:     checkpoint_paths = self.get_checkpoint_path(which_checkpoint)
[2018-05-04 10:56:45,120] {base_task_runner.py:95} INFO - Subtask:   File "/Users/sam/All-Program/App/PropertyClassification/src/conv_net/train.py", line 106, in get_checkpoint_path
[2018-05-04 10:56:45,120] {base_task_runner.py:95} INFO - Subtask:     checkpoints = [str(filename.split('.')[0]) for filename in os.listdir(self.ckpt_path)
[2018-05-04 10:56:45,120] {base_task_runner.py:95} INFO - Subtask: FileNotFoundError: [Errno 2] No such file or directory: '/Users/sam/All-Program/App-DataSet/HouseClassification/checkpoints/sam_new/aerial_cropped/resent'
[2018-05-04 10:56:46,146] {jobs.py:2083} INFO - Task exited with return code 1
